###################################################
Error in notebook: 3D_ArchPy_geological_map.ipynb
[NbConvertApp] Converting notebook examples/07_Geological_map/3D_ArchPy_geological_map.ipynb to notebook
C:\Users\emmal\Anaconda3\envs\archpy\Lib\site-packages\zmq\_future.py:718: RuntimeWarning: Proactor event loop does not implement add_reader family of methods required for zmq. Registering an additional selector thread for add_reader support via tornado. Use `asyncio.set_event_loop_policy(WindowsSelectorEventLoopPolicy())` to avoid this warning.
  self._get_loop()
Traceback (most recent call last):
  File "C:\Users\emmal\Anaconda3\envs\archpy\Lib\site-packages\jupyter_core\utils\__init__.py", line 154, in wrapped
    asyncio.get_running_loop()
RuntimeError: no running event loop

During handling of the above exception, another exception occurred:

Traceback (most recent call last):
  File "<frozen runpy>", line 198, in _run_module_as_main
  File "<frozen runpy>", line 88, in _run_code
  File "C:\Users\emmal\Anaconda3\envs\archpy\Scripts\jupyter-nbconvert.EXE\__main__.py", line 7, in <module>
  File "C:\Users\emmal\Anaconda3\envs\archpy\Lib\site-packages\jupyter_core\application.py", line 284, in launch_instance
    super().launch_instance(argv=argv, **kwargs)
  File "C:\Users\emmal\Anaconda3\envs\archpy\Lib\site-packages\traitlets\config\application.py", line 1075, in launch_instance
    app.start()
  File "C:\Users\emmal\Anaconda3\envs\archpy\Lib\site-packages\nbconvert\nbconvertapp.py", line 420, in start
    self.convert_notebooks()
  File "C:\Users\emmal\Anaconda3\envs\archpy\Lib\site-packages\nbconvert\nbconvertapp.py", line 597, in convert_notebooks
    self.convert_single_notebook(notebook_filename)
  File "C:\Users\emmal\Anaconda3\envs\archpy\Lib\site-packages\nbconvert\nbconvertapp.py", line 563, in convert_single_notebook
    output, resources = self.export_single_notebook(
                        ^^^^^^^^^^^^^^^^^^^^^^^^^^^^
  File "C:\Users\emmal\Anaconda3\envs\archpy\Lib\site-packages\nbconvert\nbconvertapp.py", line 487, in export_single_notebook
    output, resources = self.exporter.from_filename(
                        ^^^^^^^^^^^^^^^^^^^^^^^^^^^^
  File "C:\Users\emmal\Anaconda3\envs\archpy\Lib\site-packages\nbconvert\exporters\exporter.py", line 201, in from_filename
    return self.from_file(f, resources=resources, **kw)
           ^^^^^^^^^^^^^^^^^^^^^^^^^^^^^^^^^^^^^^^^^^^^
  File "C:\Users\emmal\Anaconda3\envs\archpy\Lib\site-packages\nbconvert\exporters\exporter.py", line 220, in from_file
    return self.from_notebook_node(
           ^^^^^^^^^^^^^^^^^^^^^^^^
  File "C:\Users\emmal\Anaconda3\envs\archpy\Lib\site-packages\nbconvert\exporters\notebook.py", line 36, in from_notebook_node
    nb_copy, resources = super().from_notebook_node(nb, resources, **kw)
                         ^^^^^^^^^^^^^^^^^^^^^^^^^^^^^^^^^^^^^^^^^^^^^^^
  File "C:\Users\emmal\Anaconda3\envs\archpy\Lib\site-packages\nbconvert\exporters\exporter.py", line 154, in from_notebook_node
    nb_copy, resources = self._preprocess(nb_copy, resources)
                         ^^^^^^^^^^^^^^^^^^^^^^^^^^^^^^^^^^^^
  File "C:\Users\emmal\Anaconda3\envs\archpy\Lib\site-packages\nbconvert\exporters\exporter.py", line 353, in _preprocess
    nbc, resc = preprocessor(nbc, resc)
                ^^^^^^^^^^^^^^^^^^^^^^^
  File "C:\Users\emmal\Anaconda3\envs\archpy\Lib\site-packages\nbconvert\preprocessors\base.py", line 48, in __call__
    return self.preprocess(nb, resources)
           ^^^^^^^^^^^^^^^^^^^^^^^^^^^^^^
  File "C:\Users\emmal\Anaconda3\envs\archpy\Lib\site-packages\nbconvert\preprocessors\execute.py", line 103, in preprocess
    self.preprocess_cell(cell, resources, index)
  File "C:\Users\emmal\Anaconda3\envs\archpy\Lib\site-packages\nbconvert\preprocessors\execute.py", line 124, in preprocess_cell
    cell = self.execute_cell(cell, index, store_history=True)
           ^^^^^^^^^^^^^^^^^^^^^^^^^^^^^^^^^^^^^^^^^^^^^^^^^^
  File "C:\Users\emmal\Anaconda3\envs\archpy\Lib\site-packages\jupyter_core\utils\__init__.py", line 158, in wrapped
    return loop.run_until_complete(inner)
           ^^^^^^^^^^^^^^^^^^^^^^^^^^^^^^
  File "C:\Users\emmal\Anaconda3\envs\archpy\Lib\asyncio\base_events.py", line 654, in run_until_complete
    return future.result()
           ^^^^^^^^^^^^^^^
  File "C:\Users\emmal\Anaconda3\envs\archpy\Lib\site-packages\nbclient\client.py", line 1062, in async_execute_cell
    await self._check_raise_for_error(cell, cell_index, exec_reply)
  File "C:\Users\emmal\Anaconda3\envs\archpy\Lib\site-packages\nbclient\client.py", line 918, in _check_raise_for_error
    raise CellExecutionError.from_cell_and_msg(cell, exec_reply_content)
nbclient.exceptions.CellExecutionError: An error occurred while executing the following cell:
------------------
T1.process_geological_map(typ="uniform", step=3)
------------------


[31m---------------------------------------------------------------------------[39m
[31mTypeError[39m                                 Traceback (most recent call last)
[36mCell[39m[36m [39m[32mIn[20][39m[32m, line 1[39m
[32m----> [39m[32m1[39m [43mT1[49m[43m.[49m[43mprocess_geological_map[49m[43m([49m[43mtyp[49m[43m=[49m[33;43m"[39;49m[33;43muniform[39;49m[33;43m"[39;49m[43m,[49m[43m [49m[43mstep[49m[43m=[49m[32;43m3[39;49m[43m)[49m

[31mTypeError[39m: Arch_table.process_geological_map() got an unexpected keyword argument 'step'

###################################################
Error in notebook: example.ipynb
[NbConvertApp] Converting notebook examples/10_rotation_grid/example.ipynb to notebook
C:\Users\emmal\Anaconda3\envs\archpy\Lib\site-packages\zmq\_future.py:718: RuntimeWarning: Proactor event loop does not implement add_reader family of methods required for zmq. Registering an additional selector thread for add_reader support via tornado. Use `asyncio.set_event_loop_policy(WindowsSelectorEventLoopPolicy())` to avoid this warning.
  self._get_loop()
Traceback (most recent call last):
  File "C:\Users\emmal\Anaconda3\envs\archpy\Lib\site-packages\jupyter_core\utils\__init__.py", line 154, in wrapped
    asyncio.get_running_loop()
RuntimeError: no running event loop

During handling of the above exception, another exception occurred:

Traceback (most recent call last):
  File "<frozen runpy>", line 198, in _run_module_as_main
  File "<frozen runpy>", line 88, in _run_code
  File "C:\Users\emmal\Anaconda3\envs\archpy\Scripts\jupyter-nbconvert.EXE\__main__.py", line 7, in <module>
  File "C:\Users\emmal\Anaconda3\envs\archpy\Lib\site-packages\jupyter_core\application.py", line 284, in launch_instance
    super().launch_instance(argv=argv, **kwargs)
  File "C:\Users\emmal\Anaconda3\envs\archpy\Lib\site-packages\traitlets\config\application.py", line 1075, in launch_instance
    app.start()
  File "C:\Users\emmal\Anaconda3\envs\archpy\Lib\site-packages\nbconvert\nbconvertapp.py", line 420, in start
    self.convert_notebooks()
  File "C:\Users\emmal\Anaconda3\envs\archpy\Lib\site-packages\nbconvert\nbconvertapp.py", line 597, in convert_notebooks
    self.convert_single_notebook(notebook_filename)
  File "C:\Users\emmal\Anaconda3\envs\archpy\Lib\site-packages\nbconvert\nbconvertapp.py", line 563, in convert_single_notebook
    output, resources = self.export_single_notebook(
                        ^^^^^^^^^^^^^^^^^^^^^^^^^^^^
  File "C:\Users\emmal\Anaconda3\envs\archpy\Lib\site-packages\nbconvert\nbconvertapp.py", line 487, in export_single_notebook
    output, resources = self.exporter.from_filename(
                        ^^^^^^^^^^^^^^^^^^^^^^^^^^^^
  File "C:\Users\emmal\Anaconda3\envs\archpy\Lib\site-packages\nbconvert\exporters\exporter.py", line 201, in from_filename
    return self.from_file(f, resources=resources, **kw)
           ^^^^^^^^^^^^^^^^^^^^^^^^^^^^^^^^^^^^^^^^^^^^
  File "C:\Users\emmal\Anaconda3\envs\archpy\Lib\site-packages\nbconvert\exporters\exporter.py", line 220, in from_file
    return self.from_notebook_node(
           ^^^^^^^^^^^^^^^^^^^^^^^^
  File "C:\Users\emmal\Anaconda3\envs\archpy\Lib\site-packages\nbconvert\exporters\notebook.py", line 36, in from_notebook_node
    nb_copy, resources = super().from_notebook_node(nb, resources, **kw)
                         ^^^^^^^^^^^^^^^^^^^^^^^^^^^^^^^^^^^^^^^^^^^^^^^
  File "C:\Users\emmal\Anaconda3\envs\archpy\Lib\site-packages\nbconvert\exporters\exporter.py", line 154, in from_notebook_node
    nb_copy, resources = self._preprocess(nb_copy, resources)
                         ^^^^^^^^^^^^^^^^^^^^^^^^^^^^^^^^^^^^
  File "C:\Users\emmal\Anaconda3\envs\archpy\Lib\site-packages\nbconvert\exporters\exporter.py", line 353, in _preprocess
    nbc, resc = preprocessor(nbc, resc)
                ^^^^^^^^^^^^^^^^^^^^^^^
  File "C:\Users\emmal\Anaconda3\envs\archpy\Lib\site-packages\nbconvert\preprocessors\base.py", line 48, in __call__
    return self.preprocess(nb, resources)
           ^^^^^^^^^^^^^^^^^^^^^^^^^^^^^^
  File "C:\Users\emmal\Anaconda3\envs\archpy\Lib\site-packages\nbconvert\preprocessors\execute.py", line 103, in preprocess
    self.preprocess_cell(cell, resources, index)
  File "C:\Users\emmal\Anaconda3\envs\archpy\Lib\site-packages\nbconvert\preprocessors\execute.py", line 124, in preprocess_cell
    cell = self.execute_cell(cell, index, store_history=True)
           ^^^^^^^^^^^^^^^^^^^^^^^^^^^^^^^^^^^^^^^^^^^^^^^^^^
  File "C:\Users\emmal\Anaconda3\envs\archpy\Lib\site-packages\jupyter_core\utils\__init__.py", line 158, in wrapped
    return loop.run_until_complete(inner)
           ^^^^^^^^^^^^^^^^^^^^^^^^^^^^^^
  File "C:\Users\emmal\Anaconda3\envs\archpy\Lib\asyncio\base_events.py", line 654, in run_until_complete
    return future.result()
           ^^^^^^^^^^^^^^^
  File "C:\Users\emmal\Anaconda3\envs\archpy\Lib\site-packages\nbclient\client.py", line 1062, in async_execute_cell
    await self._check_raise_for_error(cell, cell_index, exec_reply)
  File "C:\Users\emmal\Anaconda3\envs\archpy\Lib\site-packages\nbclient\client.py", line 918, in _check_raise_for_error
    raise CellExecutionError.from_cell_and_msg(cell, exec_reply_content)
nbclient.exceptions.CellExecutionError: An error occurred while executing the following cell:
------------------
T2.process_geological_map(step=10, typ="uniform")
------------------


[31m---------------------------------------------------------------------------[39m
[31mTypeError[39m                                 Traceback (most recent call last)
[36mCell[39m[36m [39m[32mIn[30][39m[32m, line 1[39m
[32m----> [39m[32m1[39m [43mT2[49m[43m.[49m[43mprocess_geological_map[49m[43m([49m[43mstep[49m[43m=[49m[32;43m10[39;49m[43m,[49m[43m [49m[43mtyp[49m[43m=[49m[33;43m"[39;49m[33;43muniform[39;49m[33;43m"[39;49m[43m)[49m

[31mTypeError[39m: Arch_table.process_geological_map() got an unexpected keyword argument 'step'

